I'm sorry, but an uncaught exception occurred.

While running game code:
  File "game/script.rpy", line 26, in script call
    call MyRoom
  File "game/script.rpy", line 103, in script
    $ inventory.remove('mirror')
  File "game/script.rpy", line 103, in <module>
    $ inventory.remove('mirror')
ValueError: list.remove(x): x not in list

-- Full Traceback ------------------------------------------------------------

Full traceback:
  File "game/script.rpy", line 26, in script call
    call MyRoom
  File "game/script.rpy", line 103, in script
    $ inventory.remove('mirror')
  File "/Applications/renpy-7.4.11-sdk/renpy/ast.py", line 928, in execute
    renpy.python.py_exec_bytecode(self.code.bytecode, self.hide, store=self.store)
  File "/Applications/renpy-7.4.11-sdk/renpy/python.py", line 2245, in py_exec_bytecode
    exec(bytecode, globals, locals)
  File "game/script.rpy", line 103, in <module>
    $ inventory.remove('mirror')
  File "/Applications/renpy-7.4.11-sdk/renpy/python.py", line 875, in do_mutation
    return method(self, *args, **kwargs)
ValueError: list.remove(x): x not in list

Darwin-21.6.0-x86_64-i386-64bit
Ren'Py 7.4.11.2266
Puzzle Test 1 1.0
Tue Jun 27 17:34:14 2023
