I'm sorry, but an uncaught exception occurred.

While running game code:
  File "game/script.rpy", line 45, in script call
    call MyRoom from _call_MyRoom
  File "game/script.rpy", line 64, in script call
    $ check_intro_reactions(current_room)
  File "game/script.rpy", line 665, in script
    $ gameOver = true
  File "game/script.rpy", line 665, in <module>
    $ gameOver = true
NameError: name 'true' is not defined

-- Full Traceback ------------------------------------------------------------

Full traceback:
  File "game/script.rpy", line 45, in script call
    call MyRoom from _call_MyRoom
  File "game/script.rpy", line 64, in script call
    $ check_intro_reactions(current_room)
  File "game/script.rpy", line 665, in script
    $ gameOver = true
  File "/Applications/renpy-7.4.11-sdk/renpy/ast.py", line 928, in execute
    renpy.python.py_exec_bytecode(self.code.bytecode, self.hide, store=self.store)
  File "/Applications/renpy-7.4.11-sdk/renpy/python.py", line 2245, in py_exec_bytecode
    exec(bytecode, globals, locals)
  File "game/script.rpy", line 665, in <module>
    $ gameOver = true
NameError: name 'true' is not defined

Darwin-21.6.0-x86_64-i386-64bit
Ren'Py 7.4.11.2266
Puzzle Test 1 1.0
Mon Jul  3 17:32:45 2023
